Workbook

Sheet Sheet1
C1: DATE | D1: DATE | E1: 46268 | F1: SAMAL
A2: NO. | B2: BOOTH CODE | C2: ADDRESS | D2: OUTLETS | E2: TELLER | F2: TOTAL BETS | G2: PAY OUT | H2: COMMISSION | I2: PALAWAN | J2: SALARY
A3: 1 | B3: =SUBSTITUTE(TRIM(LEFT(D3,FIND("-",D3&"-")-1))," ","-") -> DDN-1281 | C3: =TRIM(MID(D3,FIND("-",D3)+1,LEN(D3))) -> P1 TORIL,BABAK DISTRICT,SAMAL | D3: DDN 1281-P1 TORIL,BABAK DISTRICT,SAMAL | E3: GINAROSE CAGAS | F3: =IFERROR(VLOOKUP($B3,'EOD - SEPTEMBER 3, 2026'!$B$2:$G$1004,3,FALSE()),0) -> 8909 | G3: =IFERROR(VLOOKUP($B3,'EOD - SEPTEMBER 3, 2026'!$B:$G,6,FALSE()),0) -> 7200 | H3: =F3*0.125 -> 1113.625 | I3: =F3-G3-H3 -> 595.375 | J3: =IF((AND(F3>=100,F3<5000)),$J$48,IF((AND(F3>=5000,F3<6000)),$J$49,IF((AND(F3>=6000,F3<7000)),$J$50,IF((AND(F3>=7000,F3<8000)),$J$51,IF((AND(F3>=8000,F3<9000)),$J$52,IF((AND(F3>=9000,F3<10000)),$J$53,IF((AND(F3>=10000,F3<11000)),$J$54,IF((AND(F3>=11000,F3<12000)),$J$55,IF((AND(F3>=12000,F3<13000)),$J$56,IF((AND(F3>=13000,F3<14000)),$J$57,IF((AND(F3>=14000,F3<15000)),$J$58,IF((AND(F3>=15000,F3<16000)),$J$59,IF((AND(F3>=16000,F3<17000)),$J$60,IF((AND(F3>=17000,F3<18000)),$J$61,IF((AND(F3>=18000,F3<19000)),$J$62,IF((AND(F3>=19000,F3<20000)),$J$63,IF((AND(F3>=20000,F3<21000)),$J$64,IF((AND(F3>=21000,F3<22000)),$J$65,IF((AND(F3>=22000,F3<23000)),$J$66,IF((AND(F3>=23000,F3<24000)),$J$67,IF((AND(F3>=24000,F3<25000)),$J$68,IF((AND(F3>=25000,F3<26000)),$J$69,IF((AND(F3>=26000,F3<27000)),$J$70,IF((AND(F3>=27000,F3<28000)),$J$71,IF((AND(F3>=28000,F3<29000)),$J$72,IF((AND(F3>=29000,F3<30000)),$J$73,IF((AND(F3>=30000,F3<31000)),$J$74,IF((AND(F3>=31000,F3<32000)),$J$75,IF((AND(F3>=32000,F3<33000)),$J$76,IF((AND(F3>=33000,F3<34000)),$J$77,IF((AND(F3>=34000,F3<35000)),$J$78,IF((AND(F3>=35000,F3<36000)),$J$79,IF((AND(F3>=36000,F3<37000)),$J$80,IF((AND(F3>=37000,F3<38000)),$J$81,IF((AND(F3>=38000,F3<39000)),$J$82,IF((AND(F3>=39000,F3<40000)),$J$83,IF((AND(F3>=40000,F3<41000)),$J$84,IF((AND(F3>=41000,F3<42000)),$J$85,IF((AND(F3>=42000,F3<43000)),$J$86,IF((AND(F3>=43000,F3<44000)),$J$87,IF((AND(F3>=44000,F3<45000)),$J$88,IF((AND(F3>=45000,F3<46000)),$J$89,IF((AND(F3>=46000,F3<47000)),$J$90,IF((AND(F3>=47000,F3<48000)),$J$91,IF((AND(F3>=48000,F3<49000)),$J$92,IF((AND(F3>=49000,F3<50000)),$J$93,IF((AND(F3>=50000,F3<51000)),$J$94,IF((AND(F3>=51000,F3<52000)),$J$95,IF((AND(F3>=52000,F3<53000)),$J$96,IF((AND(F3>=53000,F3<54000)),$J$97,IF((AND(F3>=54000,F3<55000)),$J$98,IF((AND(F3>=55000,F3<56000)),$J$99,IF((AND(F3>=56000,F3<57000)),$J$100,IF((AND(F3>=57000,F3<58000)),$J$101,IF((AND(F3>=58000,F3<59000)),$J$102,IF((AND(F3>=59000,F3<60000)),$J$103,IF((AND(F3>=60000,F3<61000)),$J$104,"0"))))))))))))))))))))))))))))))))))))))))))))))))))))))))) -> 330
A4: 2 | B4: =SUBSTITUTE(TRIM(LEFT(D4,FIND("-",D4&"-")-1))," ","-") -> DDN-1284 | C4: =TRIM(MID(D4,FIND("-",D4)+1,LEN(D4))) -> ZONE,7,VILLARICA,BABAK | D4: DDN 1284-ZONE,7,VILLARICA,BABAK | E4: ANGEL MAE ESTRADA | F4: =IFERROR(VLOOKUP($B4,'EOD - SEPTEMBER 3, 2026'!$B$2:$G$1004,3,FALSE()),0) -> 3600 | G4: =IFERROR(VLOOKUP($B4,'EOD - SEPTEMBER 3, 2026'!$B:$G,6,FALSE()),0) -> 0 | H4: =F4*0.125 -> 450 | I4: =F4-G4-H4 -> 3150 | J4: =IF((AND(F4>=100,F4<5000)),$J$48,IF((AND(F4>=5000,F4<6000)),$J$49,IF((AND(F4>=6000,F4<7000)),$J$50,IF((AND(F4>=7000,F4<8000)),$J$51,IF((AND(F4>=8000,F4<9000)),$J$52,IF((AND(F4>=9000,F4<10000)),$J$53,IF((AND(F4>=10000,F4<11000)),$J$54,IF((AND(F4>=11000,F4<12000)),$J$55,IF((AND(F4>=12000,F4<13000)),$J$56,IF((AND(F4>=13000,F4<14000)),$J$57,IF((AND(F4>=14000,F4<15000)),$J$58,IF((AND(F4>=15000,F4<16000)),$J$59,IF((AND(F4>=16000,F4<17000)),$J$60,IF((AND(F4>=17000,F4<18000)),$J$61,IF((AND(F4>=18000,F4<19000)),$J$62,IF((AND(F4>=19000,F4<20000)),$J$63,IF((AND(F4>=20000,F4<21000)),$J$64,IF((AND(F4>=21000,F4<22000)),$J$65,IF((AND(F4>=22000,F4<23000)),$J$66,IF((AND(F4>=23000,F4<24000)),$J$67,IF((AND(F4>=24000,F4<25000)),$J$68,IF((AND(F4>=25000,F4<26000)),$J$69,IF((AND(F4>=26000,F4<27000)),$J$70,IF((AND(F4>=27000,F4<28000)),$J$71,IF((AND(F4>=28000,F4<29000)),$J$72,IF((AND(F4>=29000,F4<30000)),$J$73,IF((AND(F4>=30000,F4<31000)),$J$74,IF((AND(F4>=31000,F4<32000)),$J$75,IF((AND(F4>=32000,F4<33000)),$J$76,IF((AND(F4>=33000,F4<34000)),$J$77,IF((AND(F4>=34000,F4<35000)),$J$78,IF((AND(F4>=35000,F4<36000)),$J$79,IF((AND(F4>=36000,F4<37000)),$J$80,IF((AND(F4>=37000,F4<38000)),$J$81,IF((AND(F4>=38000,F4<39000)),$J$82,IF((AND(F4>=39000,F4<40000)),$J$83,IF((AND(F4>=40000,F4<41000)),$J$84,IF((AND(F4>=41000,F4<42000)),$J$85,IF((AND(F4>=42000,F4<43000)),$J$86,IF((AND(F4>=43000,F4<44000)),$J$87,IF((AND(F4>=44000,F4<45000)),$J$88,IF((AND(F4>=45000,F4<46000)),$J$89,IF((AND(F4>=46000,F4<47000)),$J$90,IF((AND(F4>=47000,F4<48000)),$J$91,IF((AND(F4>=48000,F4<49000)),$J$92,IF((AND(F4>=49000,F4<50000)),$J$93,IF((AND(F4>=50000,F4<51000)),$J$94,IF((AND(F4>=51000,F4<52000)),$J$95,IF((AND(F4>=52000,F4<53000)),$J$96,IF((AND(F4>=53000,F4<54000)),$J$97,IF((AND(F4>=54000,F4<55000)),$J$98,IF((AND(F4>=55000,F4<56000)),$J$99,IF((AND(F4>=56000,F4<57000)),$J$100,IF((AND(F4>=57000,F4<58000)),$J$101,IF((AND(F4>=58000,F4<59000)),$J$102,IF((AND(F4>=59000,F4<60000)),$J$103,IF((AND(F4>=60000,F4<61000)),$J$104,"0"))))))))))))))))))))))))))))))))))))))))))))))))))))))))) -> 250
A5: 3 | B5: =SUBSTITUTE(TRIM(LEFT(D5,FIND("-",D5&"-")-1))," ","-") -> DDN-1285 | C5: =TRIM(MID(D5,FIND("-",D5)+1,LEN(D5))) -> P4 BONGKALAS,COGON,SAMAL | D5: DDN 1285-P4 BONGKALAS,COGON,SAMAL | E5: REJEAN PREGLO | F5: =IFERROR(VLOOKUP($B5,'EOD - SEPTEMBER 3, 2026'!$B$2:$G$1004,3,FALSE()),0) -> 1675 | G5: =IFERROR(VLOOKUP($B5,'EOD - SEPTEMBER 3, 2026'!$B:$G,6,FALSE()),0) -> 0 | H5: =F5*0.125 -> 209.375 | I5: =F5-G5-H5 -> 1465.625 | J5: =IF((AND(F5>=100,F5<5000)),$J$48,IF((AND(F5>=5000,F5<6000)),$J$49,IF((AND(F5>=6000,F5<7000)),$J$50,IF((AND(F5>=7000,F5<8000)),$J$51,IF((AND(F5>=8000,F5<9000)),$J$52,IF((AND(F5>=9000,F5<10000)),$J$53,IF((AND(F5>=10000,F5<11000)),$J$54,IF((AND(F5>=11000,F5<12000)),$J$55,IF((AND(F5>=12000,F5<13000)),$J$56,IF((AND(F5>=13000,F5<14000)),$J$57,IF((AND(F5>=14000,F5<15000)),$J$58,IF((AND(F5>=15000,F5<16000)),$J$59,IF((AND(F5>=16000,F5<17000)),$J$60,IF((AND(F5>=17000,F5<18000)),$J$61,IF((AND(F5>=18000,F5<19000)),$J$62,IF((AND(F5>=19000,F5<20000)),$J$63,IF((AND(F5>=20000,F5<21000)),$J$64,IF((AND(F5>=21000,F5<22000)),$J$65,IF((AND(F5>=22000,F5<23000)),$J$66,IF((AND(F5>=23000,F5<24000)),$J$67,IF((AND(F5>=24000,F5<25000)),$J$68,IF((AND(F5>=25000,F5<26000)),$J$69,IF((AND(F5>=26000,F5<27000)),$J$70,IF((AND(F5>=27000,F5<28000)),$J$71,IF((AND(F5>=28000,F5<29000)),$J$72,IF((AND(F5>=29000,F5<30000)),$J$73,IF((AND(F5>=30000,F5<31000)),$J$74,IF((AND(F5>=31000,F5<32000)),$J$75,IF((AND(F5>=32000,F5<33000)),$J$76,IF((AND(F5>=33000,F5<34000)),$J$77,IF((AND(F5>=34000,F5<35000)),$J$78,IF((AND(F5>=35000,F5<36000)),$J$79,IF((AND(F5>=36000,F5<37000)),$J$80,IF((AND(F5>=37000,F5<38000)),$J$81,IF((AND(F5>=38000,F5<39000)),$J$82,IF((AND(F5>=39000,F5<40000)),$J$83,IF((AND(F5>=40000,F5<41000)),$J$84,IF((AND(F5>=41000,F5<42000)),$J$85,IF((AND(F5>=42000,F5<43000)),$J$86,IF((AND(F5>=43000,F5<44000)),$J$87,IF((AND(F5>=44000,F5<45000)),$J$88,IF((AND(F5>=45000,F5<46000)),$J$89,IF((AND(F5>=46000,F5<47000)),$J$90,IF((AND(F5>=47000,F5<48000)),$J$91,IF((AND(F5>=48000,F5<49000)),$J$92,IF((AND(F5>=49000,F5<50000)),$J$93,IF((AND(F5>=50000,F5<51000)),$J$94,IF((AND(F5>=51000,F5<52000)),$J$95,IF((AND(F5>=52000,F5<53000)),$J$96,IF((AND(F5>=53000,F5<54000)),$J$97,IF((AND(F5>=54000,F5<55000)),$J$98,IF((AND(F5>=55000,F5<56000)),$J$99,IF((AND(F5>=56000,F5<57000)),$J$100,IF((AND(F5>=57000,F5<58000)),$J$101,IF((AND(F5>=58000,F5<59000)),$J$102,IF((AND(F5>=59000,F5<60000)),$J$103,IF((AND(F5>=60000,F5<61000)),$J$104,"0"))))))))))))))))))))))))))))))))))))))))))))))))))))))))) -> 250
A6: 4 | B6: =SUBSTITUTE(TRIM(LEFT(D6,FIND("-",D6&"-")-1))," ","-") -> DDN-1286 | C6: =TRIM(MID(D6,FIND("-",D6)+1,LEN(D6))) -> PRK1B PENAPLATA DDN | D6: DDN 1286-PRK1B PENAPLATA DDN | E6: DIANA B. CANILLO SARAGENA | F6: =IFERROR(VLOOKUP($B6,'EOD - SEPTEMBER 3, 2026'!$B$2:$G$1004,3,FALSE()),0) -> 10015 | G6: =IFERROR(VLOOKUP($B6,'EOD - SEPTEMBER 3, 2026'!$B:$G,6,FALSE()),0) -> 1200 | H6: =F6*0.125 -> 1251.875 | I6: =F6-G6-H6 -> 7563.125 | J6: =IF((AND(F6>=100,F6<5000)),$J$48,IF((AND(F6>=5000,F6<6000)),$J$49,IF((AND(F6>=6000,F6<7000)),$J$50,IF((AND(F6>=7000,F6<8000)),$J$51,IF((AND(F6>=8000,F6<9000)),$J$52,IF((AND(F6>=9000,F6<10000)),$J$53,IF((AND(F6>=10000,F6<11000)),$J$54,IF((AND(F6>=11000,F6<12000)),$J$55,IF((AND(F6>=12000,F6<13000)),$J$56,IF((AND(F6>=13000,F6<14000)),$J$57,IF((AND(F6>=14000,F6<15000)),$J$58,IF((AND(F6>=15000,F6<16000)),$J$59,IF((AND(F6>=16000,F6<17000)),$J$60,IF((AND(F6>=17000,F6<18000)),$J$61,IF((AND(F6>=18000,F6<19000)),$J$62,IF((AND(F6>=19000,F6<20000)),$J$63,IF((AND(F6>=20000,F6<21000)),$J$64,IF((AND(F6>=21000,F6<22000)),$J$65,IF((AND(F6>=22000,F6<23000)),$J$66,IF((AND(F6>=23000,F6<24000)),$J$67,IF((AND(F6>=24000,F6<25000)),$J$68,IF((AND(F6>=25000,F6<26000)),$J$69,IF((AND(F6>=26000,F6<27000)),$J$70,IF((AND(F6>=27000,F6<28000)),$J$71,IF((AND(F6>=28000,F6<29000)),$J$72,IF((AND(F6>=29000,F6<30000)),$J$73,IF((AND(F6>=30000,F6<31000)),$J$74,IF((AND(F6>=31000,F6<32000)),$J$75,IF((AND(F6>=32000,F6<33000)),$J$76,IF((AND(F6>=33000,F6<34000)),$J$77,IF((AND(F6>=34000,F6<35000)),$J$78,IF((AND(F6>=35000,F6<36000)),$J$79,IF((AND(F6>=36000,F6<37000)),$J$80,IF((AND(F6>=37000,F6<38000)),$J$81,IF((AND(F6>=38000,F6<39000)),$J$82,IF((AND(F6>=39000,F6<40000)),$J$83,IF((AND(F6>=40000,F6<41000)),$J$84,IF((AND(F6>=41000,F6<42000)),$J$85,IF((AND(F6>=42000,F6<43000)),$J$86,IF((AND(F6>=43000,F6<44000)),$J$87,IF((AND(F6>=44000,F6<45000)),$J$88,IF((AND(F6>=45000,F6<46000)),$J$89,IF((AND(F6>=46000,F6<47000)),$J$90,IF((AND(F6>=47000,F6<48000)),$J$91,IF((AND(F6>=48000,F6<49000)),$J$92,IF((AND(F6>=49000,F6<50000)),$J$93,IF((AND(F6>=50000,F6<51000)),$J$94,IF((AND(F6>=51000,F6<52000)),$J$95,IF((AND(F6>=52000,F6<53000)),$J$96,IF((AND(F6>=53000,F6<54000)),$J$97,IF((AND(F6>=54000,F6<55000)),$J$98,IF((AND(F6>=55000,F6<56000)),$J$99,IF((AND(F6>=56000,F6<57000)),$J$100,IF((AND(F6>=57000,F6<58000)),$J$101,IF((AND(F6>=58000,F6<59000)),$J$102,IF((AND(F6>=59000,F6<60000)),$J$103,IF((AND(F6>=60000,F6<61000)),$J$104,"0"))))))))))))))))))))))))))))))))))))))))))))))))))))))))) -> 350
A7: 5 | B7: =SUBSTITUTE(TRIM(LEFT(D7,FIND("-",D7&"-")-1))," ","-") -> DDN-1288 | C7: =TRIM(MID(D7,FIND("-",D7)+1,LEN(D7))) -> PRK 1 BRGY LIBUAK,BABAK | D7: DDN 1288-PRK 1 BRGY LIBUAK,BABAK | E7: Rene Daguit | F7: =IFERROR(VLOOKUP($B7,'EOD - SEPTEMBER 3, 2026'!$B$2:$G$1004,3,FALSE()),0) -> 12007 | G7: =IFERROR(VLOOKUP($B7,'EOD - SEPTEMBER 3, 2026'!$B:$G,6,FALSE()),0) -> 7200 | H7: =F7*0.125 -> 1500.875 | I7: =F7-G7-H7 -> 3306.125 | J7: =IF((AND(F7>=100,F7<5000)),$J$48,IF((AND(F7>=5000,F7<6000)),$J$49,IF((AND(F7>=6000,F7<7000)),$J$50,IF((AND(F7>=7000,F7<8000)),$J$51,IF((AND(F7>=8000,F7<9000)),$J$52,IF((AND(F7>=9000,F7<10000)),$J$53,IF((AND(F7>=10000,F7<11000)),$J$54,IF((AND(F7>=11000,F7<12000)),$J$55,IF((AND(F7>=12000,F7<13000)),$J$56,IF((AND(F7>=13000,F7<14000)),$J$57,IF((AND(F7>=14000,F7<15000)),$J$58,IF((AND(F7>=15000,F7<16000)),$J$59,IF((AND(F7>=16000,F7<17000)),$J$60,IF((AND(F7>=17000,F7<18000)),$J$61,IF((AND(F7>=18000,F7<19000)),$J$62,IF((AND(F7>=19000,F7<20000)),$J$63,IF((AND(F7>=20000,F7<21000)),$J$64,IF((AND(F7>=21000,F7<22000)),$J$65,IF((AND(F7>=22000,F7<23000)),$J$66,IF((AND(F7>=23000,F7<24000)),$J$67,IF((AND(F7>=24000,F7<25000)),$J$68,IF((AND(F7>=25000,F7<26000)),$J$69,IF((AND(F7>=26000,F7<27000)),$J$70,IF((AND(F7>=27000,F7<28000)),$J$71,IF((AND(F7>=28000,F7<29000)),$J$72,IF((AND(F7>=29000,F7<30000)),$J$73,IF((AND(F7>=30000,F7<31000)),$J$74,IF((AND(F7>=31000,F7<32000)),$J$75,IF((AND(F7>=32000,F7<33000)),$J$76,IF((AND(F7>=33000,F7<34000)),$J$77,IF((AND(F7>=34000,F7<35000)),$J$78,IF((AND(F7>=35000,F7<36000)),$J$79,IF((AND(F7>=36000,F7<37000)),$J$80,IF((AND(F7>=37000,F7<38000)),$J$81,IF((AND(F7>=38000,F7<39000)),$J$82,IF((AND(F7>=39000,F7<40000)),$J$83,IF((AND(F7>=40000,F7<41000)),$J$84,IF((AND(F7>=41000,F7<42000)),$J$85,IF((AND(F7>=42000,F7<43000)),$J$86,IF((AND(F7>=43000,F7<44000)),$J$87,IF((AND(F7>=44000,F7<45000)),$J$88,IF((AND(F7>=45000,F7<46000)),$J$89,IF((AND(F7>=46000,F7<47000)),$J$90,IF((AND(F7>=47000,F7<48000)),$J$91,IF((AND(F7>=48000,F7<49000)),$J$92,IF((AND(F7>=49000,F7<50000)),$J$93,IF((AND(F7>=50000,F7<51000)),$J$94,IF((AND(F7>=51000,F7<52000)),$J$95,IF((AND(F7>=52000,F7<53000)),$J$96,IF((AND(F7>=53000,F7<54000)),$J$97,IF((AND(F7>=54000,F7<55000)),$J$98,IF((AND(F7>=55000,F7<56000)),$J$99,IF((AND(F7>=56000,F7<57000)),$J$100,IF((AND(F7>=57000,F7<58000)),$J$101,IF((AND(F7>=58000,F7<59000)),$J$102,IF((AND(F7>=59000,F7<60000)),$J$103,IF((AND(F7>=60000,F7<61000)),$J$104,"0"))))))))))))))))))))))))))))))))))))))))))))))))))))))))) -> 370
A8: 6 | B8: =SUBSTITUTE(TRIM(LEFT(D8,FIND("-",D8&"-")-1))," ","-") -> DDN-1635 | C8: =TRIM(MID(D8,FIND("-",D8)+1,LEN(D8))) -> PRK 6 TUGUAK,COGON,BABAK | D8: DDN 1635-PRK 6 TUGUAK,COGON,BABAK | E8: MANILYN P. VILLASIN | F8: =IFERROR(VLOOKUP($B8,'EOD - SEPTEMBER 3, 2026'!$B$2:$G$1004,3,FALSE()),0) -> 0 | G8: =IFERROR(VLOOKUP($B8,'EOD - SEPTEMBER 3, 2026'!$B:$G,6,FALSE()),0) -> 0 | H8: =F8*0.125 -> 0 | I8: =F8-G8-H8 -> 0 | J8: =IF((AND(F8>=100,F8<5000)),$J$48,IF((AND(F8>=5000,F8<6000)),$J$49,IF((AND(F8>=6000,F8<7000)),$J$50,IF((AND(F8>=7000,F8<8000)),$J$51,IF((AND(F8>=8000,F8<9000)),$J$52,IF((AND(F8>=9000,F8<10000)),$J$53,IF((AND(F8>=10000,F8<11000)),$J$54,IF((AND(F8>=11000,F8<12000)),$J$55,IF((AND(F8>=12000,F8<13000)),$J$56,IF((AND(F8>=13000,F8<14000)),$J$57,IF((AND(F8>=14000,F8<15000)),$J$58,IF((AND(F8>=15000,F8<16000)),$J$59,IF((AND(F8>=16000,F8<17000)),$J$60,IF((AND(F8>=17000,F8<18000)),$J$61,IF((AND(F8>=18000,F8<19000)),$J$62,IF((AND(F8>=19000,F8<20000)),$J$63,IF((AND(F8>=20000,F8<21000)),$J$64,IF((AND(F8>=21000,F8<22000)),$J$65,IF((AND(F8>=22000,F8<23000)),$J$66,IF((AND(F8>=23000,F8<24000)),$J$67,IF((AND(F8>=24000,F8<25000)),$J$68,IF((AND(F8>=25000,F8<26000)),$J$69,IF((AND(F8>=26000,F8<27000)),$J$70,IF((AND(F8>=27000,F8<28000)),$J$71,IF((AND(F8>=28000,F8<29000)),$J$72,IF((AND(F8>=29000,F8<30000)),$J$73,IF((AND(F8>=30000,F8<31000)),$J$74,IF((AND(F8>=31000,F8<32000)),$J$75,IF((AND(F8>=32000,F8<33000)),$J$76,IF((AND(F8>=33000,F8<34000)),$J$77,IF((AND(F8>=34000,F8<35000)),$J$78,IF((AND(F8>=35000,F8<36000)),$J$79,IF((AND(F8>=36000,F8<37000)),$J$80,IF((AND(F8>=37000,F8<38000)),$J$81,IF((AND(F8>=38000,F8<39000)),$J$82,IF((AND(F8>=39000,F8<40000)),$J$83,IF((AND(F8>=40000,F8<41000)),$J$84,IF((AND(F8>=41000,F8<42000)),$J$85,IF((AND(F8>=42000,F8<43000)),$J$86,IF((AND(F8>=43000,F8<44000)),$J$87,IF((AND(F8>=44000,F8<45000)),$J$88,IF((AND(F8>=45000,F8<46000)),$J$89,IF((AND(F8>=46000,F8<47000)),$J$90,IF((AND(F8>=47000,F8<48000)),$J$91,IF((AND(F8>=48000,F8<49000)),$J$92,IF((AND(F8>=49000,F8<50000)),$J$93,IF((AND(F8>=50000,F8<51000)),$J$94,IF((AND(F8>=51000,F8<52000)),$J$95,IF((AND(F8>=52000,F8<53000)),$J$96,IF((AND(F8>=53000,F8<54000)),$J$97,IF((AND(F8>=54000,F8<55000)),$J$98,IF((AND(F8>=55000,F8<56000)),$J$99,IF((AND(F8>=56000,F8<57000)),$J$100,IF((AND(F8>=57000,F8<58000)),$J$101,IF((AND(F8>=58000,F8<59000)),$J$102,IF((AND(F8>=59000,F8<60000)),$J$103,IF((AND(F8>=60000,F8<61000)),$J$104,"0"))))))))))))))))))))))))))))))))))))))))))))))))))))))))) -> 0
A9: 7 | B9: =SUBSTITUTE(TRIM(LEFT(D9,FIND("-",D9&"-")-1))," ","-") -> DDN-1293 | C9: =TRIM(MID(D9,FIND("-",D9)+1,LEN(D9))) -> PRK 2 TAMBO,BABAK,SAMAL | D9: DDN 1293-PRK 2 TAMBO,BABAK,SAMAL | E9: NIÑA ESCALANTE | F9: =IFERROR(VLOOKUP($B9,'EOD - SEPTEMBER 3, 2026'!$B$2:$G$1004,3,FALSE()),0) -> 4527 | G9: =IFERROR(VLOOKUP($B9,'EOD - SEPTEMBER 3, 2026'!$B:$G,6,FALSE()),0) -> 2400 | H9: =F9*0.125 -> 565.875 | I9: =F9-G9-H9 -> 1561.125 | J9: =IF((AND(F9>=100,F9<5000)),$J$48,IF((AND(F9>=5000,F9<6000)),$J$49,IF((AND(F9>=6000,F9<7000)),$J$50,IF((AND(F9>=7000,F9<8000)),$J$51,IF((AND(F9>=8000,F9<9000)),$J$52,IF((AND(F9>=9000,F9<10000)),$J$53,IF((AND(F9>=10000,F9<11000)),$J$54,IF((AND(F9>=11000,F9<12000)),$J$55,IF((AND(F9>=12000,F9<13000)),$J$56,IF((AND(F9>=13000,F9<14000)),$J$57,IF((AND(F9>=14000,F9<15000)),$J$58,IF((AND(F9>=15000,F9<16000)),$J$59,IF((AND(F9>=16000,F9<17000)),$J$60,IF((AND(F9>=17000,F9<18000)),$J$61,IF((AND(F9>=18000,F9<19000)),$J$62,IF((AND(F9>=19000,F9<20000)),$J$63,IF((AND(F9>=20000,F9<21000)),$J$64,IF((AND(F9>=21000,F9<22000)),$J$65,IF((AND(F9>=22000,F9<23000)),$J$66,IF((AND(F9>=23000,F9<24000)),$J$67,IF((AND(F9>=24000,F9<25000)),$J$68,IF((AND(F9>=25000,F9<26000)),$J$69,IF((AND(F9>=26000,F9<27000)),$J$70,IF((AND(F9>=27000,F9<28000)),$J$71,IF((AND(F9>=28000,F9<29000)),$J$72,IF((AND(F9>=29000,F9<30000)),$J$73,IF((AND(F9>=30000,F9<31000)),$J$74,IF((AND(F9>=31000,F9<32000)),$J$75,IF((AND(F9>=32000,F9<33000)),$J$76,IF((AND(F9>=33000,F9<34000)),$J$77,IF((AND(F9>=34000,F9<35000)),$J$78,IF((AND(F9>=35000,F9<36000)),$J$79,IF((AND(F9>=36000,F9<37000)),$J$80,IF((AND(F9>=37000,F9<38000)),$J$81,IF((AND(F9>=38000,F9<39000)),$J$82,IF((AND(F9>=39000,F9<40000)),$J$83,IF((AND(F9>=40000,F9<41000)),$J$84,IF((AND(F9>=41000,F9<42000)),$J$85,IF((AND(F9>=42000,F9<43000)),$J$86,IF((AND(F9>=43000,F9<44000)),$J$87,IF((AND(F9>=44000,F9<45000)),$J$88,IF((AND(F9>=45000,F9<46000)),$J$89,IF((AND(F9>=46000,F9<47000)),$J$90,IF((AND(F9>=47000,F9<48000)),$J$91,IF((AND(F9>=48000,F9<49000)),$J$92,IF((AND(F9>=49000,F9<50000)),$J$93,IF((AND(F9>=50000,F9<51000)),$J$94,IF((AND(F9>=51000,F9<52000)),$J$95,IF((AND(F9>=52000,F9<53000)),$J$96,IF((AND(F9>=53000,F9<54000)),$J$97,IF((AND(F9>=54000,F9<55000)),$J$98,IF((AND(F9>=55000,F9<56000)),$J$99,IF((AND(F9>=56000,F9<57000)),$J$100,IF((AND(F9>=57000,F9<58000)),$J$101,IF((AND(F9>=58000,F9<59000)),$J$102,IF((AND(F9>=59000,F9<60000)),$J$103,IF((AND(F9>=60000,F9<61000)),$J$104,"0"))))))))))))))))))))))))))))))))))))))))))))))))))))))))) -> 250
A10: 8 | B10: =SUBSTITUTE(TRIM(LEFT(D10,FIND("-",D10&"-")-1))," ","-") -> DDN-1294 | C10: =TRIM(MID(D10,FIND("-",D10)+1,LEN(D10))) -> CIDG,P-KAIMITO,MIRANDA,BABAK | D10: DDN 1294-CIDG,P-KAIMITO,MIRANDA,BABAK | E10: JOVILYN B. OCOM | F10: =IFERROR(VLOOKUP($B10,'EOD - SEPTEMBER 3, 2026'!$B$2:$G$1004,3,FALSE()),0) -> 3687 | G10: =IFERROR(VLOOKUP($B10,'EOD - SEPTEMBER 3, 2026'!$B:$G,6,FALSE()),0) -> 0 | H10: =F10*0.125 -> 460.875 | I10: =F10-G10-H10 -> 3226.125 | J10: =IF((AND(F10>=100,F10<5000)),$J$48,IF((AND(F10>=5000,F10<6000)),$J$49,IF((AND(F10>=6000,F10<7000)),$J$50,IF((AND(F10>=7000,F10<8000)),$J$51,IF((AND(F10>=8000,F10<9000)),$J$52,IF((AND(F10>=9000,F10<10000)),$J$53,IF((AND(F10>=10000,F10<11000)),$J$54,IF((AND(F10>=11000,F10<12000)),$J$55,IF((AND(F10>=12000,F10<13000)),$J$56,IF((AND(F10>=13000,F10<14000)),$J$57,IF((AND(F10>=14000,F10<15000)),$J$58,IF((AND(F10>=15000,F10<16000)),$J$59,IF((AND(F10>=16000,F10<17000)),$J$60,IF((AND(F10>=17000,F10<18000)),$J$61,IF((AND(F10>=18000,F10<19000)),$J$62,IF((AND(F10>=19000,F10<20000)),$J$63,IF((AND(F10>=20000,F10<21000)),$J$64,IF((AND(F10>=21000,F10<22000)),$J$65,IF((AND(F10>=22000,F10<23000)),$J$66,IF((AND(F10>=23000,F10<24000)),$J$67,IF((AND(F10>=24000,F10<25000)),$J$68,IF((AND(F10>=25000,F10<26000)),$J$69,IF((AND(F10>=26000,F10<27000)),$J$70,IF((AND(F10>=27000,F10<28000)),$J$71,IF((AND(F10>=28000,F10<29000)),$J$72,IF((AND(F10>=29000,F10<30000)),$J$73,IF((AND(F10>=30000,F10<31000)),$J$74,IF((AND(F10>=31000,F10<32000)),$J$75,IF((AND(F10>=32000,F10<33000)),$J$76,IF((AND(F10>=33000,F10<34000)),$J$77,IF((AND(F10>=34000,F10<35000)),$J$78,IF((AND(F10>=35000,F10<36000)),$J$79,IF((AND(F10>=36000,F10<37000)),$J$80,IF((AND(F10>=37000,F10<38000)),$J$81,IF((AND(F10>=38000,F10<39000)),$J$82,IF((AND(F10>=39000,F10<40000)),$J$83,IF((AND(F10>=40000,F10<41000)),$J$84,IF((AND(F10>=41000,F10<42000)),$J$85,IF((AND(F10>=42000,F10<43000)),$J$86,IF((AND(F10>=43000,F10<44000)),$J$87,IF((AND(F10>=44000,F10<45000)),$J$88,IF((AND(F10>=45000,F10<46000)),$J$89,IF((AND(F10>=46000,F10<47000)),$J$90,IF((AND(F10>=47000,F10<48000)),$J$91,IF((AND(F10>=48000,F10<49000)),$J$92,IF((AND(F10>=49000,F10<50000)),$J$93,IF((AND(F10>=50000,F10<51000)),$J$94,IF((AND(F10>=51000,F10<52000)),$J$95,IF((AND(F10>=52000,F10<53000)),$J$96,IF((AND(F10>=53000,F10<54000)),$J$97,IF((AND(F10>=54000,F10<55000)),$J$98,IF((AND(F10>=55000,F10<56000)),$J$99,IF((AND(F10>=56000,F10<57000)),$J$100,IF((AND(F10>=57000,F10<58000)),$J$101,IF((AND(F10>=58000,F10<59000)),$J$102,IF((AND(F10>=59000,F10<60000)),$J$103,IF((AND(F10>=60000,F10<61000)),$J$104,"0"))))))))))))))))))))))))))))))))))))))))))))))))))))))))) -> 250
A11: 9 | B11: =SUBSTITUTE(TRIM(LEFT(D11,FIND("-",D11&"-")-1))," ","-") -> DDN-1295 | C11: =TRIM(MID(D11,FIND("-",D11)+1,LEN(D11))) -> P3 KAUSWAGAN,MIRANDA,BABAK | D11: DDN 1295-P3 KAUSWAGAN,MIRANDA,BABAK | E11: GENNIEL MONTERDE | F11: =IFERROR(VLOOKUP($B11,'EOD - SEPTEMBER 3, 2026'!$B$2:$G$1004,3,FALSE()),0) -> 4775 | G11: =IFERROR(VLOOKUP($B11,'EOD - SEPTEMBER 3, 2026'!$B:$G,6,FALSE()),0) -> 0 | H11: =F11*0.125 -> 596.875 | I11: =F11-G11-H11 -> 4178.125 | J11: =IF((AND(F11>=100,F11<5000)),$J$48,IF((AND(F11>=5000,F11<6000)),$J$49,IF((AND(F11>=6000,F11<7000)),$J$50,IF((AND(F11>=7000,F11<8000)),$J$51,IF((AND(F11>=8000,F11<9000)),$J$52,IF((AND(F11>=9000,F11<10000)),$J$53,IF((AND(F11>=10000,F11<11000)),$J$54,IF((AND(F11>=11000,F11<12000)),$J$55,IF((AND(F11>=12000,F11<13000)),$J$56,IF((AND(F11>=13000,F11<14000)),$J$57,IF((AND(F11>=14000,F11<15000)),$J$58,IF((AND(F11>=15000,F11<16000)),$J$59,IF((AND(F11>=16000,F11<17000)),$J$60,IF((AND(F11>=17000,F11<18000)),$J$61,IF((AND(F11>=18000,F11<19000)),$J$62,IF((AND(F11>=19000,F11<20000)),$J$63,IF((AND(F11>=20000,F11<21000)),$J$64,IF((AND(F11>=21000,F11<22000)),$J$65,IF((AND(F11>=22000,F11<23000)),$J$66,IF((AND(F11>=23000,F11<24000)),$J$67,IF((AND(F11>=24000,F11<25000)),$J$68,IF((AND(F11>=25000,F11<26000)),$J$69,IF((AND(F11>=26000,F11<27000)),$J$70,IF((AND(F11>=27000,F11<28000)),$J$71,IF((AND(F11>=28000,F11<29000)),$J$72,IF((AND(F11>=29000,F11<30000)),$J$73,IF((AND(F11>=30000,F11<31000)),$J$74,IF((AND(F11>=31000,F11<32000)),$J$75,IF((AND(F11>=32000,F11<33000)),$J$76,IF((AND(F11>=33000,F11<34000)),$J$77,IF((AND(F11>=34000,F11<35000)),$J$78,IF((AND(F11>=35000,F11<36000)),$J$79,IF((AND(F11>=36000,F11<37000)),$J$80,IF((AND(F11>=37000,F11<38000)),$J$81,IF((AND(F11>=38000,F11<39000)),$J$82,IF((AND(F11>=39000,F11<40000)),$J$83,IF((AND(F11>=40000,F11<41000)),$J$84,IF((AND(F11>=41000,F11<42000)),$J$85,IF((AND(F11>=42000,F11<43000)),$J$86,IF((AND(F11>=43000,F11<44000)),$J$87,IF((AND(F11>=44000,F11<45000)),$J$88,IF((AND(F11>=45000,F11<46000)),$J$89,IF((AND(F11>=46000,F11<47000)),$J$90,IF((AND(F11>=47000,F11<48000)),$J$91,IF((AND(F11>=48000,F11<49000)),$J$92,IF((AND(F11>=49000,F11<50000)),$J$93,IF((AND(F11>=50000,F11<51000)),$J$94,IF((AND(F11>=51000,F11<52000)),$J$95,IF((AND(F11>=52000,F11<53000)),$J$96,IF((AND(F11>=53000,F11<54000)),$J$97,IF((AND(F11>=54000,F11<55000)),$J$98,IF((AND(F11>=55000,F11<56000)),$J$99,IF((AND(F11>=56000,F11<57000)),$J$100,IF((AND(F11>=57000,F11<58000)),$J$101,IF((AND(F11>=58000,F11<59000)),$J$102,IF((AND(F11>=59000,F11<60000)),$J$103,IF((AND(F11>=60000,F11<61000)),$J$104,"0"))))))))))))))))))))))))))))))))))))))))))))))))))))))))) -> 250
A12: 10 | B12: =SUBSTITUTE(TRIM(LEFT(D12,FIND("-",D12&"-")-1))," ","-") -> DDN-1296 | C12: =TRIM(MID(D12,FIND("-",D12)+1,LEN(D12))) -> PHASE 3 BUCARAN,TORIL,BABAK | D12: DDN 1296-PHASE 3 BUCARAN,TORIL,BABAK | E12: JELOU SALVADOR | F12: =IFERROR(VLOOKUP($B12,'EOD - SEPTEMBER 3, 2026'!$B$2:$G$1004,3,FALSE()),0) -> 2775 | G12: =IFERROR(VLOOKUP($B12,'EOD - SEPTEMBER 3, 2026'!$B:$G,6,FALSE()),0) -> 0 | H12: =F12*0.125 -> 346.875 | I12: =F12-G12-H12 -> 2428.125 | J12: =IF((AND(F12>=100,F12<5000)),$J$48,IF((AND(F12>=5000,F12<6000)),$J$49,IF((AND(F12>=6000,F12<7000)),$J$50,IF((AND(F12>=7000,F12<8000)),$J$51,IF((AND(F12>=8000,F12<9000)),$J$52,IF((AND(F12>=9000,F12<10000)),$J$53,IF((AND(F12>=10000,F12<11000)),$J$54,IF((AND(F12>=11000,F12<12000)),$J$55,IF((AND(F12>=12000,F12<13000)),$J$56,IF((AND(F12>=13000,F12<14000)),$J$57,IF((AND(F12>=14000,F12<15000)),$J$58,IF((AND(F12>=15000,F12<16000)),$J$59,IF((AND(F12>=16000,F12<17000)),$J$60,IF((AND(F12>=17000,F12<18000)),$J$61,IF((AND(F12>=18000,F12<19000)),$J$62,IF((AND(F12>=19000,F12<20000)),$J$63,IF((AND(F12>=20000,F12<21000)),$J$64,IF((AND(F12>=21000,F12<22000)),$J$65,IF((AND(F12>=22000,F12<23000)),$J$66,IF((AND(F12>=23000,F12<24000)),$J$67,IF((AND(F12>=24000,F12<25000)),$J$68,IF((AND(F12>=25000,F12<26000)),$J$69,IF((AND(F12>=26000,F12<27000)),$J$70,IF((AND(F12>=27000,F12<28000)),$J$71,IF((AND(F12>=28000,F12<29000)),$J$72,IF((AND(F12>=29000,F12<30000)),$J$73,IF((AND(F12>=30000,F12<31000)),$J$74,IF((AND(F12>=31000,F12<32000)),$J$75,IF((AND(F12>=32000,F12<33000)),$J$76,IF((AND(F12>=33000,F12<34000)),$J$77,IF((AND(F12>=34000,F12<35000)),$J$78,IF((AND(F12>=35000,F12<36000)),$J$79,IF((AND(F12>=36000,F12<37000)),$J$80,IF((AND(F12>=37000,F12<38000)),$J$81,IF((AND(F12>=38000,F12<39000)),$J$82,IF((AND(F12>=39000,F12<40000)),$J$83,IF((AND(F12>=40000,F12<41000)),$J$84,IF((AND(F12>=41000,F12<42000)),$J$85,IF((AND(F12>=42000,F12<43000)),$J$86,IF((AND(F12>=43000,F12<44000)),$J$87,IF((AND(F12>=44000,F12<45000)),$J$88,IF((AND(F12>=45000,F12<46000)),$J$89,IF((AND(F12>=46000,F12<47000)),$J$90,IF((AND(F12>=47000,F12<48000)),$J$91,IF((AND(F12>=48000,F12<49000)),$J$92,IF((AND(F12>=49000,F12<50000)),$J$93,IF((AND(F12>=50000,F12<51000)),$J$94,IF((AND(F12>=51000,F12<52000)),$J$95,IF((AND(F12>=52000,F12<53000)),$J$96,IF((AND(F12>=53000,F12<54000)),$J$97,IF((AND(F12>=54000,F12<55000)),$J$98,IF((AND(F12>=55000,F12<56000)),$J$99,IF((AND(F12>=56000,F12<57000)),$J$100,IF((AND(F12>=57000,F12<58000)),$J$101,IF((AND(F12>=58000,F12<59000)),$J$102,IF((AND(F12>=59000,F12<60000)),$J$103,IF((AND(F12>=60000,F12<61000)),$J$104,"0"))))))))))))))))))))))))))))))))))))))))))))))))))))))))) -> 250
A13: 11 | B13: =SUBSTITUTE(TRIM(LEFT(D13,FIND("-",D13&"-")-1))," ","-") -> DDN-1629 | C13: =TRIM(MID(D13,FIND("-",D13)+1,LEN(D13))) -> PRK 6 KINAWITNON,BABAK | D13: DDN 1629-PRK 6 KINAWITNON,BABAK | E13: Diomelyn Pansit Abad | F13: =IFERROR(VLOOKUP($B13,'EOD - SEPTEMBER 3, 2026'!$B$2:$G$1004,3,FALSE()),0) -> 2954 | G13: =IFERROR(VLOOKUP($B13,'EOD - SEPTEMBER 3, 2026'!$B:$G,6,FALSE()),0) -> 400 | H13: =F13*0.125 -> 369.25 | I13: =F13-G13-H13 -> 2184.75 | J13: =IF((AND(F13>=100,F13<5000)),$J$48,IF((AND(F13>=5000,F13<6000)),$J$49,IF((AND(F13>=6000,F13<7000)),$J$50,IF((AND(F13>=7000,F13<8000)),$J$51,IF((AND(F13>=8000,F13<9000)),$J$52,IF((AND(F13>=9000,F13<10000)),$J$53,IF((AND(F13>=10000,F13<11000)),$J$54,IF((AND(F13>=11000,F13<12000)),$J$55,IF((AND(F13>=12000,F13<13000)),$J$56,IF((AND(F13>=13000,F13<14000)),$J$57,IF((AND(F13>=14000,F13<15000)),$J$58,IF((AND(F13>=15000,F13<16000)),$J$59,IF((AND(F13>=16000,F13<17000)),$J$60,IF((AND(F13>=17000,F13<18000)),$J$61,IF((AND(F13>=18000,F13<19000)),$J$62,IF((AND(F13>=19000,F13<20000)),$J$63,IF((AND(F13>=20000,F13<21000)),$J$64,IF((AND(F13>=21000,F13<22000)),$J$65,IF((AND(F13>=22000,F13<23000)),$J$66,IF((AND(F13>=23000,F13<24000)),$J$67,IF((AND(F13>=24000,F13<25000)),$J$68,IF((AND(F13>=25000,F13<26000)),$J$69,IF((AND(F13>=26000,F13<27000)),$J$70,IF((AND(F13>=27000,F13<28000)),$J$71,IF((AND(F13>=28000,F13<29000)),$J$72,IF((AND(F13>=29000,F13<30000)),$J$73,IF((AND(F13>=30000,F13<31000)),$J$74,IF((AND(F13>=31000,F13<32000)),$J$75,IF((AND(F13>=32000,F13<33000)),$J$76,IF((AND(F13>=33000,F13<34000)),$J$77,IF((AND(F13>=34000,F13<35000)),$J$78,IF((AND(F13>=35000,F13<36000)),$J$79,IF((AND(F13>=36000,F13<37000)),$J$80,IF((AND(F13>=37000,F13<38000)),$J$81,IF((AND(F13>=38000,F13<39000)),$J$82,IF((AND(F13>=39000,F13<40000)),$J$83,IF((AND(F13>=40000,F13<41000)),$J$84,IF((AND(F13>=41000,F13<42000)),$J$85,IF((AND(F13>=42000,F13<43000)),$J$86,IF((AND(F13>=43000,F13<44000)),$J$87,IF((AND(F13>=44000,F13<45000)),$J$88,IF((AND(F13>=45000,F13<46000)),$J$89,IF((AND(F13>=46000,F13<47000)),$J$90,IF((AND(F13>=47000,F13<48000)),$J$91,IF((AND(F13>=48000,F13<49000)),$J$92,IF((AND(F13>=49000,F13<50000)),$J$93,IF((AND(F13>=50000,F13<51000)),$J$94,IF((AND(F13>=51000,F13<52000)),$J$95,IF((AND(F13>=52000,F13<53000)),$J$96,IF((AND(F13>=53000,F13<54000)),$J$97,IF((AND(F13>=54000,F13<55000)),$J$98,IF((AND(F13>=55000,F13<56000)),$J$99,IF((AND(F13>=56000,F13<57000)),$J$100,IF((AND(F13>=57000,F13<58000)),$J$101,IF((AND(F13>=58000,F13<59000)),$J$102,IF((AND(F13>=59000,F13<60000)),$J$103,IF((AND(F13>=60000,F13<61000)),$J$104,"0"))))))))))))))))))))))))))))))))))))))))))))))))))))))))) -> 250
A14: 12 | B14: =SUBSTITUTE(TRIM(LEFT(D14,FIND("-",D14&"-")-1))," ","-") -> DDN-1299 | C14: =TRIM(MID(D14,FIND("-",D14)+1,LEN(D14))) -> TALIPAPA,MIRANDA BABAK | D14: DDN 1299-TALIPAPA,MIRANDA BABAK | E14: AIZA CRODUA SAN JUAN | F14: =IFERROR(VLOOKUP($B14,'EOD - SEPTEMBER 3, 2026'!$B$2:$G$1004,3,FALSE()),0) -> 6067 | G14: =IFERROR(VLOOKUP($B14,'EOD - SEPTEMBER 3, 2026'!$B:$G,6,FALSE()),0) -> 1600 | H14: =F14*0.125 -> 758.375 | I14: =F14-G14-H14 -> 3708.625 | J14: =IF((AND(F14>=100,F14<5000)),$J$48,IF((AND(F14>=5000,F14<6000)),$J$49,IF((AND(F14>=6000,F14<7000)),$J$50,IF((AND(F14>=7000,F14<8000)),$J$51,IF((AND(F14>=8000,F14<9000)),$J$52,IF((AND(F14>=9000,F14<10000)),$J$53,IF((AND(F14>=10000,F14<11000)),$J$54,IF((AND(F14>=11000,F14<12000)),$J$55,IF((AND(F14>=12000,F14<13000)),$J$56,IF((AND(F14>=13000,F14<14000)),$J$57,IF((AND(F14>=14000,F14<15000)),$J$58,IF((AND(F14>=15000,F14<16000)),$J$59,IF((AND(F14>=16000,F14<17000)),$J$60,IF((AND(F14>=17000,F14<18000)),$J$61,IF((AND(F14>=18000,F14<19000)),$J$62,IF((AND(F14>=19000,F14<20000)),$J$63,IF((AND(F14>=20000,F14<21000)),$J$64,IF((AND(F14>=21000,F14<22000)),$J$65,IF((AND(F14>=22000,F14<23000)),$J$66,IF((AND(F14>=23000,F14<24000)),$J$67,IF((AND(F14>=24000,F14<25000)),$J$68,IF((AND(F14>=25000,F14<26000)),$J$69,IF((AND(F14>=26000,F14<27000)),$J$70,IF((AND(F14>=27000,F14<28000)),$J$71,IF((AND(F14>=28000,F14<29000)),$J$72,IF((AND(F14>=29000,F14<30000)),$J$73,IF((AND(F14>=30000,F14<31000)),$J$74,IF((AND(F14>=31000,F14<32000)),$J$75,IF((AND(F14>=32000,F14<33000)),$J$76,IF((AND(F14>=33000,F14<34000)),$J$77,IF((AND(F14>=34000,F14<35000)),$J$78,IF((AND(F14>=35000,F14<36000)),$J$79,IF((AND(F14>=36000,F14<37000)),$J$80,IF((AND(F14>=37000,F14<38000)),$J$81,IF((AND(F14>=38000,F14<39000)),$J$82,IF((AND(F14>=39000,F14<40000)),$J$83,IF((AND(F14>=40000,F14<41000)),$J$84,IF((AND(F14>=41000,F14<42000)),$J$85,IF((AND(F14>=42000,F14<43000)),$J$86,IF((AND(F14>=43000,F14<44000)),$J$87,IF((AND(F14>=44000,F14<45000)),$J$88,IF((AND(F14>=45000,F14<46000)),$J$89,IF((AND(F14>=46000,F14<47000)),$J$90,IF((AND(F14>=47000,F14<48000)),$J$91,IF((AND(F14>=48000,F14<49000)),$J$92,IF((AND(F14>=49000,F14<50000)),$J$93,IF((AND(F14>=50000,F14<51000)),$J$94,IF((AND(F14>=51000,F14<52000)),$J$95,IF((AND(F14>=52000,F14<53000)),$J$96,IF((AND(F14>=53000,F14<54000)),$J$97,IF((AND(F14>=54000,F14<55000)),$J$98,IF((AND(F14>=55000,F14<56000)),$J$99,IF((AND(F14>=56000,F14<57000)),$J$100,IF((AND(F14>=57000,F14<58000)),$J$101,IF((AND(F14>=58000,F14<59000)),$J$102,IF((AND(F14>=59000,F14<60000)),$J$103,IF((AND(F14>=60000,F14<61000)),$J$104,"0"))))))))))))))))))))))))))))))))))))))))))))))))))))))))) -> 310
... A21: 19 | B21: =SUBSTITUTE(TRIM(LEFT(D21,FIND("-",D21&"-")-1))," ","-") -> DDN-1588 | C21: =TRIM(MID(D21,FIND("-",D21)+1,LEN(D21))) -> PRK 2 STO.NINO,PENAPLATA | D21: DDN 1588-PRK 2 STO.NINO,PENAPLATA | E21: MARYJEAN BOGHANOY | F21: =IFERROR(VLOOKUP($B21,'EOD - SEPTEMBER 3, 2026'!$B$2:$G$1004,3,FALSE()),0) -> 2560 | G21: =IFERROR(VLOOKUP($B21,'EOD - SEPTEMBER 3, 2026'!$B:$G,6,FALSE()),0) -> 800 | H21: =F21*0.125 -> 320 | I21: =F21-G21-H21 -> 1440 | J21: =IF((AND(F21>=100,F21<5000)),$J$48,IF((AND(F21>=5000,F21<6000)),$J$49,IF((AND(F21>=6000,F21<7000)),$J$50,IF((AND(F21>=7000,F21<8000)),$J$51,IF((AND(F21>=8000,F21<9000)),$J$52,IF((AND(F21>=9000,F21<10000)),$J$53,IF((AND(F21>=10000,F21<11000)),$J$54,IF((AND(F21>=11000,F21<12000)),$J$55,IF((AND(F21>=12000,F21<13000)),$J$56,IF((AND(F21>=13000,F21<14000)),$J$57,IF((AND(F21>=14000,F21<15000)),$J$58,IF((AND(F21>=15000,F21<16000)),$J$59,IF((AND(F21>=16000,F21<17000)),$J$60,IF((AND(F21>=17000,F21<18000)),$J$61,IF((AND(F21>=18000,F21<19000)),$J$62,IF((AND(F21>=19000,F21<20000)),$J$63,IF((AND(F21>=20000,F21<21000)),$J$64,IF((AND(F21>=21000,F21<22000)),$J$65,IF((AND(F21>=22000,F21<23000)),$J$66,IF((AND(F21>=23000,F21<24000)),$J$67,IF((AND(F21>=24000,F21<25000)),$J$68,IF((AND(F21>=25000,F21<26000)),$J$69,IF((AND(F21>=26000,F21<27000)),$J$70,IF((AND(F21>=27000,F21<28000)),$J$71,IF((AND(F21>=28000,F21<29000)),$J$72,IF((AND(F21>=29000,F21<30000)),$J$73,IF((AND(F21>=30000,F21<31000)),$J$74,IF((AND(F21>=31000,F21<32000)),$J$75,IF((AND(F21>=32000,F21<33000)),$J$76,IF((AND(F21>=33000,F21<34000)),$J$77,IF((AND(F21>=34000,F21<35000)),$J$78,IF((AND(F21>=35000,F21<36000)),$J$79,IF((AND(F21>=36000,F21<37000)),$J$80,IF((AND(F21>=37000,F21<38000)),$J$81,IF((AND(F21>=38000,F21<39000)),$J$82,IF((AND(F21>=39000,F21<40000)),$J$83,IF((AND(F21>=40000,F21<41000)),$J$84,IF((AND(F21>=41000,F21<42000)),$J$85,IF((AND(F21>=42000,F21<43000)),$J$86,IF((AND(F21>=43000,F21<44000)),$J$87,IF((AND(F21>=44000,F21<45000)),$J$88,IF((AND(F21>=45000,F21<46000)),$J$89,IF((AND(F21>=46000,F21<47000)),$J$90,IF((AND(F21>=47000,F21<48000)),$J$91,IF((AND(F21>=48000,F21<49000)),$J$92,IF((AND(F21>=49000,F21<50000)),$J$93,IF((AND(F21>=50000,F21<51000)),$J$94,IF((AND(F21>=51000,F21<52000)),$J$95,IF((AND(F21>=52000,F21<53000)),$J$96,IF((AND(F21>=53000,F21<54000)),$J$97,IF((AND(F21>=54000,F21<55000)),$J$98,IF((AND(F21>=55000,F21<56000)),$J$99,IF((AND(F21>=56000,F21<57000)),$J$100,IF((AND(F21>=57000,F21<58000)),$J$101,IF((AND(F21>=58000,F21<59000)),$J$102,IF((AND(F21>=59000,F21<60000)),$J$103,IF((AND(F21>=60000,F21<61000)),$J$104,"0"))))))))))))))))))))))))))))))))))))))))))))))))))))))))) -> 250
A22: 20 | B22: =SUBSTITUTE(TRIM(LEFT(D22,FIND("-",D22&"-")-1))," ","-") -> DDN-1589 | C22: =TRIM(MID(D22,FIND("-",D22)+1,LEN(D22))) -> KINAWITNON,BABAK DISTRICT (TEMPORARY DEACTIVATED) | D22: DDN 1589-KINAWITNON,BABAK DISTRICT (TEMPORARY DEACTIVATED) | F22: =IFERROR(VLOOKUP($B22,'EOD - SEPTEMBER 3, 2026'!$B$2:$G$1004,3,FALSE()),0) -> 0 | G22: =IFERROR(VLOOKUP($B22,'EOD - SEPTEMBER 3, 2026'!$B:$G,6,FALSE()),0) -> 0 | H22: =F22*0.125 -> 0 | I22: =F22-G22-H22 -> 0 | J22: =IF((AND(F22>=100,F22<5000)),$J$48,IF((AND(F22>=5000,F22<6000)),$J$49,IF((AND(F22>=6000,F22<7000)),$J$50,IF((AND(F22>=7000,F22<8000)),$J$51,IF((AND(F22>=8000,F22<9000)),$J$52,IF((AND(F22>=9000,F22<10000)),$J$53,IF((AND(F22>=10000,F22<11000)),$J$54,IF((AND(F22>=11000,F22<12000)),$J$55,IF((AND(F22>=12000,F22<13000)),$J$56,IF((AND(F22>=13000,F22<14000)),$J$57,IF((AND(F22>=14000,F22<15000)),$J$58,IF((AND(F22>=15000,F22<16000)),$J$59,IF((AND(F22>=16000,F22<17000)),$J$60,IF((AND(F22>=17000,F22<18000)),$J$61,IF((AND(F22>=18000,F22<19000)),$J$62,IF((AND(F22>=19000,F22<20000)),$J$63,IF((AND(F22>=20000,F22<21000)),$J$64,IF((AND(F22>=21000,F22<22000)),$J$65,IF((AND(F22>=22000,F22<23000)),$J$66,IF((AND(F22>=23000,F22<24000)),$J$67,IF((AND(F22>=24000,F22<25000)),$J$68,IF((AND(F22>=25000,F22<26000)),$J$69,IF((AND(F22>=26000,F22<27000)),$J$70,IF((AND(F22>=27000,F22<28000)),$J$71,IF((AND(F22>=28000,F22<29000)),$J$72,IF((AND(F22>=29000,F22<30000)),$J$73,IF((AND(F22>=30000,F22<31000)),$J$74,IF((AND(F22>=31000,F22<32000)),$J$75,IF((AND(F22>=32000,F22<33000)),$J$76,IF((AND(F22>=33000,F22<34000)),$J$77,IF((AND(F22>=34000,F22<35000)),$J$78,IF((AND(F22>=35000,F22<36000)),$J$79,IF((AND(F22>=36000,F22<37000)),$J$80,IF((AND(F22>=37000,F22<38000)),$J$81,IF((AND(F22>=38000,F22<39000)),$J$82,IF((AND(F22>=39000,F22<40000)),$J$83,IF((AND(F22>=40000,F22<41000)),$J$84,IF((AND(F22>=41000,F22<42000)),$J$85,IF((AND(F22>=42000,F22<43000)),$J$86,IF((AND(F22>=43000,F22<44000)),$J$87,IF((AND(F22>=44000,F22<45000)),$J$88,IF((AND(F22>=45000,F22<46000)),$J$89,IF((AND(F22>=46000,F22<47000)),$J$90,IF((AND(F22>=47000,F22<48000)),$J$91,IF((AND(F22>=48000,F22<49000)),$J$92,IF((AND(F22>=49000,F22<50000)),$J$93,IF((AND(F22>=50000,F22<51000)),$J$94,IF((AND(F22>=51000,F22<52000)),$J$95,IF((AND(F22>=52000,F22<53000)),$J$96,IF((AND(F22>=53000,F22<54000)),$J$97,IF((AND(F22>=54000,F22<55000)),$J$98,IF((AND(F22>=55000,F22<56000)),$J$99,IF((AND(F22>=56000,F22<57000)),$J$100,IF((AND(F22>=57000,F22<58000)),$J$101,IF((AND(F22>=58000,F22<59000)),$J$102,IF((AND(F22>=59000,F22<60000)),$J$103,IF((AND(F22>=60000,F22<61000)),$J$104,"0"))))))))))))))))))))))))))))))))))))))))))))))))))))))))) -> 0
A23: 21 | B23: =SUBSTITUTE(TRIM(LEFT(D23,FIND("-",D23&"-")-1))," ","-") -> DDN-1630 | C23: =TRIM(MID(D23,FIND("-",D23)+1,LEN(D23))) -> Prk 7, ANUNANG, KAPUTIAN, IGACOS (TEMPORARY DEACTIVATED) | D23: DDN 1630-Prk 7, ANUNANG, KAPUTIAN, IGACOS (TEMPORARY DEACTIVATED) | F23: =IFERROR(VLOOKUP($B23,'EOD - SEPTEMBER 3, 2026'!$B$2:$G$1004,3,FALSE()),0) -> 0 | G23: =IFERROR(VLOOKUP($B23,'EOD - SEPTEMBER 3, 2026'!$B:$G,6,FALSE()),0) -> 0 | H23: =F23*0.125 -> 0 | I23: =F23-G23-H23 -> 0 | J23: =IF((AND(F23>=100,F23<5000)),$J$48,IF((AND(F23>=5000,F23<6000)),$J$49,IF((AND(F23>=6000,F23<7000)),$J$50,IF((AND(F23>=7000,F23<8000)),$J$51,IF((AND(F23>=8000,F23<9000)),$J$52,IF((AND(F23>=9000,F23<10000)),$J$53,IF((AND(F23>=10000,F23<11000)),$J$54,IF((AND(F23>=11000,F23<12000)),$J$55,IF((AND(F23>=12000,F23<13000)),$J$56,IF((AND(F23>=13000,F23<14000)),$J$57,IF((AND(F23>=14000,F23<15000)),$J$58,IF((AND(F23>=15000,F23<16000)),$J$59,IF((AND(F23>=16000,F23<17000)),$J$60,IF((AND(F23>=17000,F23<18000)),$J$61,IF((AND(F23>=18000,F23<19000)),$J$62,IF((AND(F23>=19000,F23<20000)),$J$63,IF((AND(F23>=20000,F23<21000)),$J$64,IF((AND(F23>=21000,F23<22000)),$J$65,IF((AND(F23>=22000,F23<23000)),$J$66,IF((AND(F23>=23000,F23<24000)),$J$67,IF((AND(F23>=24000,F23<25000)),$J$68,IF((AND(F23>=25000,F23<26000)),$J$69,IF((AND(F23>=26000,F23<27000)),$J$70,IF((AND(F23>=27000,F23<28000)),$J$71,IF((AND(F23>=28000,F23<29000)),$J$72,IF((AND(F23>=29000,F23<30000)),$J$73,IF((AND(F23>=30000,F23<31000)),$J$74,IF((AND(F23>=31000,F23<32000)),$J$75,IF((AND(F23>=32000,F23<33000)),$J$76,IF((AND(F23>=33000,F23<34000)),$J$77,IF((AND(F23>=34000,F23<35000)),$J$78,IF((AND(F23>=35000,F23<36000)),$J$79,IF((AND(F23>=36000,F23<37000)),$J$80,IF((AND(F23>=37000,F23<38000)),$J$81,IF((AND(F23>=38000,F23<39000)),$J$82,IF((AND(F23>=39000,F23<40000)),$J$83,IF((AND(F23>=40000,F23<41000)),$J$84,IF((AND(F23>=41000,F23<42000)),$J$85,IF((AND(F23>=42000,F23<43000)),$J$86,IF((AND(F23>=43000,F23<44000)),$J$87,IF((AND(F23>=44000,F23<45000)),$J$88,IF((AND(F23>=45000,F23<46000)),$J$89,IF((AND(F23>=46000,F23<47000)),$J$90,IF((AND(F23>=47000,F23<48000)),$J$91,IF((AND(F23>=48000,F23<49000)),$J$92,IF((AND(F23>=49000,F23<50000)),$J$93,IF((AND(F23>=50000,F23<51000)),$J$94,IF((AND(F23>=51000,F23<52000)),$J$95,IF((AND(F23>=52000,F23<53000)),$J$96,IF((AND(F23>=53000,F23<54000)),$J$97,IF((AND(F23>=54000,F23<55000)),$J$98,IF((AND(F23>=55000,F23<56000)),$J$99,IF((AND(F23>=56000,F23<57000)),$J$100,IF((AND(F23>=57000,F23<58000)),$J$101,IF((AND(F23>=58000,F23<59000)),$J$102,IF((AND(F23>=59000,F23<60000)),$J$103,IF((AND(F23>=60000,F23<61000)),$J$104,"0"))))))))))))))))))))))))))))))))))))))))))))))))))))))))) -> 0
A24: 22 | B24: =SUBSTITUTE(TRIM(LEFT(D24,FIND("-",D24&"-")-1))," ","-") -> DDN-1631 | C24: =TRIM(MID(D24,FIND("-",D24)+1,LEN(D24))) -> PORUK 3, AUMBAY, SAMAL | D24: DDN 1631-PORUK 3, AUMBAY, SAMAL | E24: AMABELLE GIAN | F24: =IFERROR(VLOOKUP($B24,'EOD - SEPTEMBER 3, 2026'!$B$2:$G$1004,3,FALSE()),0) -> 2640 | G24: =IFERROR(VLOOKUP($B24,'EOD - SEPTEMBER 3, 2026'!$B:$G,6,FALSE()),0) -> 0 | H24: =F24*0.125 -> 330 | I24: =F24-G24-H24 -> 2310 | J24: =IF((AND(F24>=100,F24<5000)),$J$48,IF((AND(F24>=5000,F24<6000)),$J$49,IF((AND(F24>=6000,F24<7000)),$J$50,IF((AND(F24>=7000,F24<8000)),$J$51,IF((AND(F24>=8000,F24<9000)),$J$52,IF((AND(F24>=9000,F24<10000)),$J$53,IF((AND(F24>=10000,F24<11000)),$J$54,IF((AND(F24>=11000,F24<12000)),$J$55,IF((AND(F24>=12000,F24<13000)),$J$56,IF((AND(F24>=13000,F24<14000)),$J$57,IF((AND(F24>=14000,F24<15000)),$J$58,IF((AND(F24>=15000,F24<16000)),$J$59,IF((AND(F24>=16000,F24<17000)),$J$60,IF((AND(F24>=17000,F24<18000)),$J$61,IF((AND(F24>=18000,F24<19000)),$J$62,IF((AND(F24>=19000,F24<20000)),$J$63,IF((AND(F24>=20000,F24<21000)),$J$64,IF((AND(F24>=21000,F24<22000)),$J$65,IF((AND(F24>=22000,F24<23000)),$J$66,IF((AND(F24>=23000,F24<24000)),$J$67,IF((AND(F24>=24000,F24<25000)),$J$68,IF((AND(F24>=25000,F24<26000)),$J$69,IF((AND(F24>=26000,F24<27000)),$J$70,IF((AND(F24>=27000,F24<28000)),$J$71,IF((AND(F24>=28000,F24<29000)),$J$72,IF((AND(F24>=29000,F24<30000)),$J$73,IF((AND(F24>=30000,F24<31000)),$J$74,IF((AND(F24>=31000,F24<32000)),$J$75,IF((AND(F24>=32000,F24<33000)),$J$76,IF((AND(F24>=33000,F24<34000)),$J$77,IF((AND(F24>=34000,F24<35000)),$J$78,IF((AND(F24>=35000,F24<36000)),$J$79,IF((AND(F24>=36000,F24<37000)),$J$80,IF((AND(F24>=37000,F24<38000)),$J$81,IF((AND(F24>=38000,F24<39000)),$J$82,IF((AND(F24>=39000,F24<40000)),$J$83,IF((AND(F24>=40000,F24<41000)),$J$84,IF((AND(F24>=41000,F24<42000)),$J$85,IF((AND(F24>=42000,F24<43000)),$J$86,IF((AND(F24>=43000,F24<44000)),$J$87,IF((AND(F24>=44000,F24<45000)),$J$88,IF((AND(F24>=45000,F24<46000)),$J$89,IF((AND(F24>=46000,F24<47000)),$J$90,IF((AND(F24>=47000,F24<48000)),$J$91,IF((AND(F24>=48000,F24<49000)),$J$92,IF((AND(F24>=49000,F24<50000)),$J$93,IF((AND(F24>=50000,F24<51000)),$J$94,IF((AND(F24>=51000,F24<52000)),$J$95,IF((AND(F24>=52000,F24<53000)),$J$96,IF((AND(F24>=53000,F24<54000)),$J$97,IF((AND(F24>=54000,F24<55000)),$J$98,IF((AND(F24>=55000,F24<56000)),$J$99,IF((AND(F24>=56000,F24<57000)),$J$100,IF((AND(F24>=57000,F24<58000)),$J$101,IF((AND(F24>=58000,F24<59000)),$J$102,IF((AND(F24>=59000,F24<60000)),$J$103,IF((AND(F24>=60000,F24<61000)),$J$104,"0"))))))))))))))))))))))))))))))))))))))))))))))))))))))))) -> 250
A25: 23 | B25: =SUBSTITUTE(TRIM(LEFT(D25,FIND("-",D25&"-")-1))," ","-") -> DDN-1632 | C25: =TRIM(MID(D25,FIND("-",D25)+1,LEN(D25))) -> PUROK 1, TAGBAY SAMAL | D25: DDN 1632-PUROK 1, TAGBAY SAMAL | E25: Jeralyne Marcellones | F25: =IFERROR(VLOOKUP($B25,'EOD - SEPTEMBER 3, 2026'!$B$2:$G$1004,3,FALSE()),0) -> 3790 | G25: =IFERROR(VLOOKUP($B25,'EOD - SEPTEMBER 3, 2026'!$B:$G,6,FALSE()),0) -> 2000 | H25: =F25*0.125 -> 473.75 | I25: =F25-G25-H25 -> 1316.25 | J25: =IF((AND(F25>=100,F25<5000)),$J$48,IF((AND(F25>=5000,F25<6000)),$J$49,IF((AND(F25>=6000,F25<7000)),$J$50,IF((AND(F25>=7000,F25<8000)),$J$51,IF((AND(F25>=8000,F25<9000)),$J$52,IF((AND(F25>=9000,F25<10000)),$J$53,IF((AND(F25>=10000,F25<11000)),$J$54,IF((AND(F25>=11000,F25<12000)),$J$55,IF((AND(F25>=12000,F25<13000)),$J$56,IF((AND(F25>=13000,F25<14000)),$J$57,IF((AND(F25>=14000,F25<15000)),$J$58,IF((AND(F25>=15000,F25<16000)),$J$59,IF((AND(F25>=16000,F25<17000)),$J$60,IF((AND(F25>=17000,F25<18000)),$J$61,IF((AND(F25>=18000,F25<19000)),$J$62,IF((AND(F25>=19000,F25<20000)),$J$63,IF((AND(F25>=20000,F25<21000)),$J$64,IF((AND(F25>=21000,F25<22000)),$J$65,IF((AND(F25>=22000,F25<23000)),$J$66,IF((AND(F25>=23000,F25<24000)),$J$67,IF((AND(F25>=24000,F25<25000)),$J$68,IF((AND(F25>=25000,F25<26000)),$J$69,IF((AND(F25>=26000,F25<27000)),$J$70,IF((AND(F25>=27000,F25<28000)),$J$71,IF((AND(F25>=28000,F25<29000)),$J$72,IF((AND(F25>=29000,F25<30000)),$J$73,IF((AND(F25>=30000,F25<31000)),$J$74,IF((AND(F25>=31000,F25<32000)),$J$75,IF((AND(F25>=32000,F25<33000)),$J$76,IF((AND(F25>=33000,F25<34000)),$J$77,IF((AND(F25>=34000,F25<35000)),$J$78,IF((AND(F25>=35000,F25<36000)),$J$79,IF((AND(F25>=36000,F25<37000)),$J$80,IF((AND(F25>=37000,F25<38000)),$J$81,IF((AND(F25>=38000,F25<39000)),$J$82,IF((AND(F25>=39000,F25<40000)),$J$83,IF((AND(F25>=40000,F25<41000)),$J$84,IF((AND(F25>=41000,F25<42000)),$J$85,IF((AND(F25>=42000,F25<43000)),$J$86,IF((AND(F25>=43000,F25<44000)),$J$87,IF((AND(F25>=44000,F25<45000)),$J$88,IF((AND(F25>=45000,F25<46000)),$J$89,IF((AND(F25>=46000,F25<47000)),$J$90,IF((AND(F25>=47000,F25<48000)),$J$91,IF((AND(F25>=48000,F25<49000)),$J$92,IF((AND(F25>=49000,F25<50000)),$J$93,IF((AND(F25>=50000,F25<51000)),$J$94,IF((AND(F25>=51000,F25<52000)),$J$95,IF((AND(F25>=52000,F25<53000)),$J$96,IF((AND(F25>=53000,F25<54000)),$J$97,IF((AND(F25>=54000,F25<55000)),$J$98,IF((AND(F25>=55000,F25<56000)),$J$99,IF((AND(F25>=56000,F25<57000)),$J$100,IF((AND(F25>=57000,F25<58000)),$J$101,IF((AND(F25>=58000,F25<59000)),$J$102,IF((AND(F25>=59000,F25<60000)),$J$103,IF((AND(F25>=60000,F25<61000)),$J$104,"0"))))))))))))))))))))))))))))))))))))))))))))))))))))))))) -> 250
A26: 24 | B26: =SUBSTITUTE(TRIM(LEFT(D26,FIND("-",D26&"-")-1))," ","-") -> DDN-1634 | C26: =TRIM(MID(D26,FIND("-",D26)+1,LEN(D26))) -> TAGBITINAO, GUILON | D26: DDN 1634- TAGBITINAO, GUILON | E26: ILLAINE YBAÑEZ | F26: =IFERROR(VLOOKUP($B26,'EOD - SEPTEMBER 3, 2026'!$B$2:$G$1004,3,FALSE()),0) -> 5420 | G26: =IFERROR(VLOOKUP($B26,'EOD - SEPTEMBER 3, 2026'!$B:$G,6,FALSE()),0) -> 0 | H26: =F26*0.125 -> 677.5 | I26: =F26-G26-H26 -> 4742.5 | J26: =IF((AND(F26>=100,F26<5000)),$J$48,IF((AND(F26>=5000,F26<6000)),$J$49,IF((AND(F26>=6000,F26<7000)),$J$50,IF((AND(F26>=7000,F26<8000)),$J$51,IF((AND(F26>=8000,F26<9000)),$J$52,IF((AND(F26>=9000,F26<10000)),$J$53,IF((AND(F26>=10000,F26<11000)),$J$54,IF((AND(F26>=11000,F26<12000)),$J$55,IF((AND(F26>=12000,F26<13000)),$J$56,IF((AND(F26>=13000,F26<14000)),$J$57,IF((AND(F26>=14000,F26<15000)),$J$58,IF((AND(F26>=15000,F26<16000)),$J$59,IF((AND(F26>=16000,F26<17000)),$J$60,IF((AND(F26>=17000,F26<18000)),$J$61,IF((AND(F26>=18000,F26<19000)),$J$62,IF((AND(F26>=19000,F26<20000)),$J$63,IF((AND(F26>=20000,F26<21000)),$J$64,IF((AND(F26>=21000,F26<22000)),$J$65,IF((AND(F26>=22000,F26<23000)),$J$66,IF((AND(F26>=23000,F26<24000)),$J$67,IF((AND(F26>=24000,F26<25000)),$J$68,IF((AND(F26>=25000,F26<26000)),$J$69,IF((AND(F26>=26000,F26<27000)),$J$70,IF((AND(F26>=27000,F26<28000)),$J$71,IF((AND(F26>=28000,F26<29000)),$J$72,IF((AND(F26>=29000,F26<30000)),$J$73,IF((AND(F26>=30000,F26<31000)),$J$74,IF((AND(F26>=31000,F26<32000)),$J$75,IF((AND(F26>=32000,F26<33000)),$J$76,IF((AND(F26>=33000,F26<34000)),$J$77,IF((AND(F26>=34000,F26<35000)),$J$78,IF((AND(F26>=35000,F26<36000)),$J$79,IF((AND(F26>=36000,F26<37000)),$J$80,IF((AND(F26>=37000,F26<38000)),$J$81,IF((AND(F26>=38000,F26<39000)),$J$82,IF((AND(F26>=39000,F26<40000)),$J$83,IF((AND(F26>=40000,F26<41000)),$J$84,IF((AND(F26>=41000,F26<42000)),$J$85,IF((AND(F26>=42000,F26<43000)),$J$86,IF((AND(F26>=43000,F26<44000)),$J$87,IF((AND(F26>=44000,F26<45000)),$J$88,IF((AND(F26>=45000,F26<46000)),$J$89,IF((AND(F26>=46000,F26<47000)),$J$90,IF((AND(F26>=47000,F26<48000)),$J$91,IF((AND(F26>=48000,F26<49000)),$J$92,IF((AND(F26>=49000,F26<50000)),$J$93,IF((AND(F26>=50000,F26<51000)),$J$94,IF((AND(F26>=51000,F26<52000)),$J$95,IF((AND(F26>=52000,F26<53000)),$J$96,IF((AND(F26>=53000,F26<54000)),$J$97,IF((AND(F26>=54000,F26<55000)),$J$98,IF((AND(F26>=55000,F26<56000)),$J$99,IF((AND(F26>=56000,F26<57000)),$J$100,IF((AND(F26>=57000,F26<58000)),$J$101,IF((AND(F26>=58000,F26<59000)),$J$102,IF((AND(F26>=59000,F26<60000)),$J$103,IF((AND(F26>=60000,F26<61000)),$J$104,"0"))))))))))))))))))))))))))))))))))))))))))))))))))))))))) -> 300
A27: 25 | B27: =SUBSTITUTE(TRIM(LEFT(D27,FIND("-",D27&"-")-1))," ","-") -> DDN-1679 | C27: =TRIM(MID(D27,FIND("-",D27)+1,LEN(D27))) -> P4 CAWAG, IGACOS | D27: DDN 1679- P4 CAWAG, IGACOS | E27: Jasmine Nicole J. Gila | F27: =IFERROR(VLOOKUP($B27,'EOD - SEPTEMBER 3, 2026'!$B$2:$G$1004,3,FALSE()),0) -> 5880 | G27: =IFERROR(VLOOKUP($B27,'EOD - SEPTEMBER 3, 2026'!$B:$G,6,FALSE()),0) -> 0 | H27: =F27*0.125 -> 735 | I27: =F27-G27-H27 -> 5145 | J27: =IF((AND(F27>=100,F27<5000)),$J$48,IF((AND(F27>=5000,F27<6000)),$J$49,IF((AND(F27>=6000,F27<7000)),$J$50,IF((AND(F27>=7000,F27<8000)),$J$51,IF((AND(F27>=8000,F27<9000)),$J$52,IF((AND(F27>=9000,F27<10000)),$J$53,IF((AND(F27>=10000,F27<11000)),$J$54,IF((AND(F27>=11000,F27<12000)),$J$55,IF((AND(F27>=12000,F27<13000)),$J$56,IF((AND(F27>=13000,F27<14000)),$J$57,IF((AND(F27>=14000,F27<15000)),$J$58,IF((AND(F27>=15000,F27<16000)),$J$59,IF((AND(F27>=16000,F27<17000)),$J$60,IF((AND(F27>=17000,F27<18000)),$J$61,IF((AND(F27>=18000,F27<19000)),$J$62,IF((AND(F27>=19000,F27<20000)),$J$63,IF((AND(F27>=20000,F27<21000)),$J$64,IF((AND(F27>=21000,F27<22000)),$J$65,IF((AND(F27>=22000,F27<23000)),$J$66,IF((AND(F27>=23000,F27<24000)),$J$67,IF((AND(F27>=24000,F27<25000)),$J$68,IF((AND(F27>=25000,F27<26000)),$J$69,IF((AND(F27>=26000,F27<27000)),$J$70,IF((AND(F27>=27000,F27<28000)),$J$71,IF((AND(F27>=28000,F27<29000)),$J$72,IF((AND(F27>=29000,F27<30000)),$J$73,IF((AND(F27>=30000,F27<31000)),$J$74,IF((AND(F27>=31000,F27<32000)),$J$75,IF((AND(F27>=32000,F27<33000)),$J$76,IF((AND(F27>=33000,F27<34000)),$J$77,IF((AND(F27>=34000,F27<35000)),$J$78,IF((AND(F27>=35000,F27<36000)),$J$79,IF((AND(F27>=36000,F27<37000)),$J$80,IF((AND(F27>=37000,F27<38000)),$J$81,IF((AND(F27>=38000,F27<39000)),$J$82,IF((AND(F27>=39000,F27<40000)),$J$83,IF((AND(F27>=40000,F27<41000)),$J$84,IF((AND(F27>=41000,F27<42000)),$J$85,IF((AND(F27>=42000,F27<43000)),$J$86,IF((AND(F27>=43000,F27<44000)),$J$87,IF((AND(F27>=44000,F27<45000)),$J$88,IF((AND(F27>=45000,F27<46000)),$J$89,IF((AND(F27>=46000,F27<47000)),$J$90,IF((AND(F27>=47000,F27<48000)),$J$91,IF((AND(F27>=48000,F27<49000)),$J$92,IF((AND(F27>=49000,F27<50000)),$J$93,IF((AND(F27>=50000,F27<51000)),$J$94,IF((AND(F27>=51000,F27<52000)),$J$95,IF((AND(F27>=52000,F27<53000)),$J$96,IF((AND(F27>=53000,F27<54000)),$J$97,IF((AND(F27>=54000,F27<55000)),$J$98,IF((AND(F27>=55000,F27<56000)),$J$99,IF((AND(F27>=56000,F27<57000)),$J$100,IF((AND(F27>=57000,F27<58000)),$J$101,IF((AND(F27>=58000,F27<59000)),$J$102,IF((AND(F27>=59000,F27<60000)),$J$103,IF((AND(F27>=60000,F27<61000)),$J$104,"0"))))))))))))))))))))))))))))))))))))))))))))))))))))))))) -> 300
A28: 26 | B28: =SUBSTITUTE(TRIM(LEFT(D28,FIND("-",D28&"-")-1))," ","-") -> DDN-1714 | C28: =TRIM(MID(D28,FIND("-",D28)+1,LEN(D28))) -> PUROK 1, CAWAG | D28: DDN 1714-PUROK 1, CAWAG | E28: Reisthlle Ann D. Dapiton | F28: =IFERROR(VLOOKUP($B28,'EOD - SEPTEMBER 3, 2026'!$B$2:$G$1004,3,FALSE()),0) -> 3765 | G28: =IFERROR(VLOOKUP($B28,'EOD - SEPTEMBER 3, 2026'!$B:$G,6,FALSE()),0) -> 2400 | H28: =F28*0.125 -> 470.625 | I28: =F28-G28-H28 -> 894.375 | J28: =IF((AND(F28>=100,F28<5000)),$J$48,IF((AND(F28>=5000,F28<6000)),$J$49,IF((AND(F28>=6000,F28<7000)),$J$50,IF((AND(F28>=7000,F28<8000)),$J$51,IF((AND(F28>=8000,F28<9000)),$J$52,IF((AND(F28>=9000,F28<10000)),$J$53,IF((AND(F28>=10000,F28<11000)),$J$54,IF((AND(F28>=11000,F28<12000)),$J$55,IF((AND(F28>=12000,F28<13000)),$J$56,IF((AND(F28>=13000,F28<14000)),$J$57,IF((AND(F28>=14000,F28<15000)),$J$58,IF((AND(F28>=15000,F28<16000)),$J$59,IF((AND(F28>=16000,F28<17000)),$J$60,IF((AND(F28>=17000,F28<18000)),$J$61,IF((AND(F28>=18000,F28<19000)),$J$62,IF((AND(F28>=19000,F28<20000)),$J$63,IF((AND(F28>=20000,F28<21000)),$J$64,IF((AND(F28>=21000,F28<22000)),$J$65,IF((AND(F28>=22000,F28<23000)),$J$66,IF((AND(F28>=23000,F28<24000)),$J$67,IF((AND(F28>=24000,F28<25000)),$J$68,IF((AND(F28>=25000,F28<26000)),$J$69,IF((AND(F28>=26000,F28<27000)),$J$70,IF((AND(F28>=27000,F28<28000)),$J$71,IF((AND(F28>=28000,F28<29000)),$J$72,IF((AND(F28>=29000,F28<30000)),$J$73,IF((AND(F28>=30000,F28<31000)),$J$74,IF((AND(F28>=31000,F28<32000)),$J$75,IF((AND(F28>=32000,F28<33000)),$J$76,IF((AND(F28>=33000,F28<34000)),$J$77,IF((AND(F28>=34000,F28<35000)),$J$78,IF((AND(F28>=35000,F28<36000)),$J$79,IF((AND(F28>=36000,F28<37000)),$J$80,IF((AND(F28>=37000,F28<38000)),$J$81,IF((AND(F28>=38000,F28<39000)),$J$82,IF((AND(F28>=39000,F28<40000)),$J$83,IF((AND(F28>=40000,F28<41000)),$J$84,IF((AND(F28>=41000,F28<42000)),$J$85,IF((AND(F28>=42000,F28<43000)),$J$86,IF((AND(F28>=43000,F28<44000)),$J$87,IF((AND(F28>=44000,F28<45000)),$J$88,IF((AND(F28>=45000,F28<46000)),$J$89,IF((AND(F28>=46000,F28<47000)),$J$90,IF((AND(F28>=47000,F28<48000)),$J$91,IF((AND(F28>=48000,F28<49000)),$J$92,IF((AND(F28>=49000,F28<50000)),$J$93,IF((AND(F28>=50000,F28<51000)),$J$94,IF((AND(F28>=51000,F28<52000)),$J$95,IF((AND(F28>=52000,F28<53000)),$J$96,IF((AND(F28>=53000,F28<54000)),$J$97,IF((AND(F28>=54000,F28<55000)),$J$98,IF((AND(F28>=55000,F28<56000)),$J$99,IF((AND(F28>=56000,F28<57000)),$J$100,IF((AND(F28>=57000,F28<58000)),$J$101,IF((AND(F28>=58000,F28<59000)),$J$102,IF((AND(F28>=59000,F28<60000)),$J$103,IF((AND(F28>=60000,F28<61000)),$J$104,"0"))))))))))))))))))))))))))))))))))))))))))))))))))))))))) -> 250
A29: 27 | B29: =SUBSTITUTE(TRIM(LEFT(D29,FIND("-",D29&"-")-1))," ","-") -> DDN-1737 | C29: =TRIM(MID(D29,FIND("-",D29)+1,LEN(D29))) -> PUROK 3B PARAISO CAWAG | D29: DDN 1737 - PUROK 3B PARAISO CAWAG | E29: Loraine Junatas | F29: =IFERROR(VLOOKUP($B29,'EOD - SEPTEMBER 3, 2026'!$B$2:$G$1004,3,FALSE()),0) -> 2660 | G29: =IFERROR(VLOOKUP($B29,'EOD - SEPTEMBER 3, 2026'!$B:$G,6,FALSE()),0) -> 1200 | H29: =F29*0.125 -> 332.5 | I29: =F29-G29-H29 -> 1127.5 | J29: =IF((AND(F29>=100,F29<5000)),$J$48,IF((AND(F29>=5000,F29<6000)),$J$49,IF((AND(F29>=6000,F29<7000)),$J$50,IF((AND(F29>=7000,F29<8000)),$J$51,IF((AND(F29>=8000,F29<9000)),$J$52,IF((AND(F29>=9000,F29<10000)),$J$53,IF((AND(F29>=10000,F29<11000)),$J$54,IF((AND(F29>=11000,F29<12000)),$J$55,IF((AND(F29>=12000,F29<13000)),$J$56,IF((AND(F29>=13000,F29<14000)),$J$57,IF((AND(F29>=14000,F29<15000)),$J$58,IF((AND(F29>=15000,F29<16000)),$J$59,IF((AND(F29>=16000,F29<17000)),$J$60,IF((AND(F29>=17000,F29<18000)),$J$61,IF((AND(F29>=18000,F29<19000)),$J$62,IF((AND(F29>=19000,F29<20000)),$J$63,IF((AND(F29>=20000,F29<21000)),$J$64,IF((AND(F29>=21000,F29<22000)),$J$65,IF((AND(F29>=22000,F29<23000)),$J$66,IF((AND(F29>=23000,F29<24000)),$J$67,IF((AND(F29>=24000,F29<25000)),$J$68,IF((AND(F29>=25000,F29<26000)),$J$69,IF((AND(F29>=26000,F29<27000)),$J$70,IF((AND(F29>=27000,F29<28000)),$J$71,IF((AND(F29>=28000,F29<29000)),$J$72,IF((AND(F29>=29000,F29<30000)),$J$73,IF((AND(F29>=30000,F29<31000)),$J$74,IF((AND(F29>=31000,F29<32000)),$J$75,IF((AND(F29>=32000,F29<33000)),$J$76,IF((AND(F29>=33000,F29<34000)),$J$77,IF((AND(F29>=34000,F29<35000)),$J$78,IF((AND(F29>=35000,F29<36000)),$J$79,IF((AND(F29>=36000,F29<37000)),$J$80,IF((AND(F29>=37000,F29<38000)),$J$81,IF((AND(F29>=38000,F29<39000)),$J$82,IF((AND(F29>=39000,F29<40000)),$J$83,IF((AND(F29>=40000,F29<41000)),$J$84,IF((AND(F29>=41000,F29<42000)),$J$85,IF((AND(F29>=42000,F29<43000)),$J$86,IF((AND(F29>=43000,F29<44000)),$J$87,IF((AND(F29>=44000,F29<45000)),$J$88,IF((AND(F29>=45000,F29<46000)),$J$89,IF((AND(F29>=46000,F29<47000)),$J$90,IF((AND(F29>=47000,F29<48000)),$J$91,IF((AND(F29>=48000,F29<49000)),$J$92,IF((AND(F29>=49000,F29<50000)),$J$93,IF((AND(F29>=50000,F29<51000)),$J$94,IF((AND(F29>=51000,F29<52000)),$J$95,IF((AND(F29>=52000,F29<53000)),$J$96,IF((AND(F29>=53000,F29<54000)),$J$97,IF((AND(F29>=54000,F29<55000)),$J$98,IF((AND(F29>=55000,F29<56000)),$J$99,IF((AND(F29>=56000,F29<57000)),$J$100,IF((AND(F29>=57000,F29<58000)),$J$101,IF((AND(F29>=58000,F29<59000)),$J$102,IF((AND(F29>=59000,F29<60000)),$J$103,IF((AND(F29>=60000,F29<61000)),$J$104,"0"))))))))))))))))))))))))))))))))))))))))))))))))))))))))) -> 250
A30: 28 | B30: DDN-1757 | C30: Purok 6, Aumbay, Samal City | E30: Janilyn Buragay Callano | F30: =IFERROR(VLOOKUP($B30,'EOD - SEPTEMBER 3, 2026'!$B$2:$G$1004,3,FALSE()),0) -> 4050 | G30: =IFERROR(VLOOKUP($B30,'EOD - SEPTEMBER 3, 2026'!$B:$G,6,FALSE()),0) -> 1600 | H30: =F30*0.125 -> 506.25 | I30: =F30-G30-H30 -> 1943.75 | J30: =IF((AND(F30>=100,F30<5000)),$J$48,IF((AND(F30>=5000,F30<6000)),$J$49,IF((AND(F30>=6000,F30<7000)),$J$50,IF((AND(F30>=7000,F30<8000)),$J$51,IF((AND(F30>=8000,F30<9000)),$J$52,IF((AND(F30>=9000,F30<10000)),$J$53,IF((AND(F30>=10000,F30<11000)),$J$54,IF((AND(F30>=11000,F30<12000)),$J$55,IF((AND(F30>=12000,F30<13000)),$J$56,IF((AND(F30>=13000,F30<14000)),$J$57,IF((AND(F30>=14000,F30<15000)),$J$58,IF((AND(F30>=15000,F30<16000)),$J$59,IF((AND(F30>=16000,F30<17000)),$J$60,IF((AND(F30>=17000,F30<18000)),$J$61,IF((AND(F30>=18000,F30<19000)),$J$62,IF((AND(F30>=19000,F30<20000)),$J$63,IF((AND(F30>=20000,F30<21000)),$J$64,IF((AND(F30>=21000,F30<22000)),$J$65,IF((AND(F30>=22000,F30<23000)),$J$66,IF((AND(F30>=23000,F30<24000)),$J$67,IF((AND(F30>=24000,F30<25000)),$J$68,IF((AND(F30>=25000,F30<26000)),$J$69,IF((AND(F30>=26000,F30<27000)),$J$70,IF((AND(F30>=27000,F30<28000)),$J$71,IF((AND(F30>=28000,F30<29000)),$J$72,IF((AND(F30>=29000,F30<30000)),$J$73,IF((AND(F30>=30000,F30<31000)),$J$74,IF((AND(F30>=31000,F30<32000)),$J$75,IF((AND(F30>=32000,F30<33000)),$J$76,IF((AND(F30>=33000,F30<34000)),$J$77,IF((AND(F30>=34000,F30<35000)),$J$78,IF((AND(F30>=35000,F30<36000)),$J$79,IF((AND(F30>=36000,F30<37000)),$J$80,IF((AND(F30>=37000,F30<38000)),$J$81,IF((AND(F30>=38000,F30<39000)),$J$82,IF((AND(F30>=39000,F30<40000)),$J$83,IF((AND(F30>=40000,F30<41000)),$J$84,IF((AND(F30>=41000,F30<42000)),$J$85,IF((AND(F30>=42000,F30<43000)),$J$86,IF((AND(F30>=43000,F30<44000)),$J$87,IF((AND(F30>=44000,F30<45000)),$J$88,IF((AND(F30>=45000,F30<46000)),$J$89,IF((AND(F30>=46000,F30<47000)),$J$90,IF((AND(F30>=47000,F30<48000)),$J$91,IF((AND(F30>=48000,F30<49000)),$J$92,IF((AND(F30>=49000,F30<50000)),$J$93,IF((AND(F30>=50000,F30<51000)),$J$94,IF((AND(F30>=51000,F30<52000)),$J$95,IF((AND(F30>=52000,F30<53000)),$J$96,IF((AND(F30>=53000,F30<54000)),$J$97,IF((AND(F30>=54000,F30<55000)),$J$98,IF((AND(F30>=55000,F30<56000)),$J$99,IF((AND(F30>=56000,F30<57000)),$J$100,IF((AND(F30>=57000,F30<58000)),$J$101,IF((AND(F30>=58000,F30<59000)),$J$102,IF((AND(F30>=59000,F30<60000)),$J$103,IF((AND(F30>=60000,F30<61000)),$J$104,"0"))))))))))))))))))))))))))))))))))))))))))))))))))))))))) -> 250
A31: 29 | B31: DDN-1758 | C31: Purok 5A Tagbay, Samal | E31: Chen A. Canillo | F31: =IFERROR(VLOOKUP($B31,'EOD - SEPTEMBER 3, 2026'!$B$2:$G$1004,3,FALSE()),0) -> 1640 | G31: =IFERROR(VLOOKUP($B31,'EOD - SEPTEMBER 3, 2026'!$B:$G,6,FALSE()),0) -> 800 | H31: =F31*0.125 -> 205 | I31: =F31-G31-H31 -> 635 | J31: =IF((AND(F31>=100,F31<5000)),$J$48,IF((AND(F31>=5000,F31<6000)),$J$49,IF((AND(F31>=6000,F31<7000)),$J$50,IF((AND(F31>=7000,F31<8000)),$J$51,IF((AND(F31>=8000,F31<9000)),$J$52,IF((AND(F31>=9000,F31<10000)),$J$53,IF((AND(F31>=10000,F31<11000)),$J$54,IF((AND(F31>=11000,F31<12000)),$J$55,IF((AND(F31>=12000,F31<13000)),$J$56,IF((AND(F31>=13000,F31<14000)),$J$57,IF((AND(F31>=14000,F31<15000)),$J$58,IF((AND(F31>=15000,F31<16000)),$J$59,IF((AND(F31>=16000,F31<17000)),$J$60,IF((AND(F31>=17000,F31<18000)),$J$61,IF((AND(F31>=18000,F31<19000)),$J$62,IF((AND(F31>=19000,F31<20000)),$J$63,IF((AND(F31>=20000,F31<21000)),$J$64,IF((AND(F31>=21000,F31<22000)),$J$65,IF((AND(F31>=22000,F31<23000)),$J$66,IF((AND(F31>=23000,F31<24000)),$J$67,IF((AND(F31>=24000,F31<25000)),$J$68,IF((AND(F31>=25000,F31<26000)),$J$69,IF((AND(F31>=26000,F31<27000)),$J$70,IF((AND(F31>=27000,F31<28000)),$J$71,IF((AND(F31>=28000,F31<29000)),$J$72,IF((AND(F31>=29000,F31<30000)),$J$73,IF((AND(F31>=30000,F31<31000)),$J$74,IF((AND(F31>=31000,F31<32000)),$J$75,IF((AND(F31>=32000,F31<33000)),$J$76,IF((AND(F31>=33000,F31<34000)),$J$77,IF((AND(F31>=34000,F31<35000)),$J$78,IF((AND(F31>=35000,F31<36000)),$J$79,IF((AND(F31>=36000,F31<37000)),$J$80,IF((AND(F31>=37000,F31<38000)),$J$81,IF((AND(F31>=38000,F31<39000)),$J$82,IF((AND(F31>=39000,F31<40000)),$J$83,IF((AND(F31>=40000,F31<41000)),$J$84,IF((AND(F31>=41000,F31<42000)),$J$85,IF((AND(F31>=42000,F31<43000)),$J$86,IF((AND(F31>=43000,F31<44000)),$J$87,IF((AND(F31>=44000,F31<45000)),$J$88,IF((AND(F31>=45000,F31<46000)),$J$89,IF((AND(F31>=46000,F31<47000)),$J$90,IF((AND(F31>=47000,F31<48000)),$J$91,IF((AND(F31>=48000,F31<49000)),$J$92,IF((AND(F31>=49000,F31<50000)),$J$93,IF((AND(F31>=50000,F31<51000)),$J$94,IF((AND(F31>=51000,F31<52000)),$J$95,IF((AND(F31>=52000,F31<53000)),$J$96,IF((AND(F31>=53000,F31<54000)),$J$97,IF((AND(F31>=54000,F31<55000)),$J$98,IF((AND(F31>=55000,F31<56000)),$J$99,IF((AND(F31>=56000,F31<57000)),$J$100,IF((AND(F31>=57000,F31<58000)),$J$101,IF((AND(F31>=58000,F31<59000)),$J$102,IF((AND(F31>=59000,F31<60000)),$J$103,IF((AND(F31>=60000,F31<61000)),$J$104,"0"))))))))))))))))))))))))))))))))))))))))))))))))))))))))) -> 250
